[2023-04-21 10:41:15,883] {taskinstance.py:1159} INFO - Dependencies all met for <TaskInstance: First_DAG.bash_task_copy_data manual__2023-04-21T10:36:11.519484+00:00 [queued]>
[2023-04-21 10:41:15,890] {taskinstance.py:1159} INFO - Dependencies all met for <TaskInstance: First_DAG.bash_task_copy_data manual__2023-04-21T10:36:11.519484+00:00 [queued]>
[2023-04-21 10:41:15,891] {taskinstance.py:1356} INFO - 
--------------------------------------------------------------------------------
[2023-04-21 10:41:15,892] {taskinstance.py:1357} INFO - Starting attempt 2 of 2
[2023-04-21 10:41:15,892] {taskinstance.py:1358} INFO - 
--------------------------------------------------------------------------------
[2023-04-21 10:41:15,908] {taskinstance.py:1377} INFO - Executing <Task(BashOperator): bash_task_copy_data> on 2023-04-21 10:36:11.519484+00:00
[2023-04-21 10:41:15,912] {standard_task_runner.py:52} INFO - Started process 424 to run task
[2023-04-21 10:41:15,914] {standard_task_runner.py:79} INFO - Running: ['***', 'tasks', 'run', 'First_DAG', 'bash_task_copy_data', 'manual__2023-04-21T10:36:11.519484+00:00', '--job-id', '29', '--raw', '--subdir', 'DAGS_FOLDER/first.py', '--cfg-path', '/tmp/tmp87_puy_l', '--error-file', '/tmp/tmp3p6wvbbg']
[2023-04-21 10:41:15,915] {standard_task_runner.py:80} INFO - Job 29: Subtask bash_task_copy_data
[2023-04-21 10:41:15,962] {task_command.py:369} INFO - Running <TaskInstance: First_DAG.bash_task_copy_data manual__2023-04-21T10:36:11.519484+00:00 [running]> on host 9975a0282eea
[2023-04-21 10:41:16,028] {taskinstance.py:1571} INFO - Exporting the following env vars:
AIRFLOW_CTX_DAG_OWNER=***
AIRFLOW_CTX_DAG_ID=First_DAG
AIRFLOW_CTX_TASK_ID=bash_task_copy_data
AIRFLOW_CTX_EXECUTION_DATE=2023-04-21T10:36:11.519484+00:00
AIRFLOW_CTX_TRY_NUMBER=2
AIRFLOW_CTX_DAG_RUN_ID=manual__2023-04-21T10:36:11.519484+00:00
[2023-04-21 10:41:16,030] {subprocess.py:62} INFO - Tmp dir root location: 
 /tmp
[2023-04-21 10:41:16,031] {subprocess.py:74} INFO - Running command: ['bash', '-c', 'cp /Users/glzma/onur/***_test/data/DATA_CENTER/DATA_LAKE/dataset_raw.txt /Users/glzma/onur/***_test/data/DATA_CENTER/CLEAN_DATA']
[2023-04-21 10:41:16,041] {subprocess.py:85} INFO - Output:
[2023-04-21 10:41:16,044] {subprocess.py:92} INFO - cp: cannot stat '/Users/glzma/onur/***_test/data/DATA_CENTER/DATA_LAKE/dataset_raw.txt': No such file or directory
[2023-04-21 10:41:16,044] {subprocess.py:96} INFO - Command exited with return code 1
[2023-04-21 10:41:16,057] {taskinstance.py:1889} ERROR - Task failed with exception
Traceback (most recent call last):
  File "/home/airflow/.local/lib/python3.7/site-packages/airflow/operators/bash.py", line 195, in execute
    f'Bash command failed. The command returned a non-zero exit code {result.exit_code}.'
airflow.exceptions.AirflowException: Bash command failed. The command returned a non-zero exit code 1.
[2023-04-21 10:41:16,060] {taskinstance.py:1400} INFO - Marking task as FAILED. dag_id=First_DAG, task_id=bash_task_copy_data, execution_date=20230421T103611, start_date=20230421T104115, end_date=20230421T104116
[2023-04-21 10:41:16,071] {standard_task_runner.py:97} ERROR - Failed to execute job 29 for task bash_task_copy_data (Bash command failed. The command returned a non-zero exit code 1.; 424)
[2023-04-21 10:41:16,087] {local_task_job.py:156} INFO - Task exited with return code 1
[2023-04-21 10:41:16,123] {local_task_job.py:273} INFO - 0 downstream tasks scheduled from follow-on schedule check
