[2023-04-21 11:05:42,030] {taskinstance.py:1159} INFO - Dependencies all met for <TaskInstance: First_DAG.bash_task_copy_data manual__2023-04-21T11:05:39.699725+00:00 [queued]>
[2023-04-21 11:05:42,038] {taskinstance.py:1159} INFO - Dependencies all met for <TaskInstance: First_DAG.bash_task_copy_data manual__2023-04-21T11:05:39.699725+00:00 [queued]>
[2023-04-21 11:05:42,039] {taskinstance.py:1356} INFO - 
--------------------------------------------------------------------------------
[2023-04-21 11:05:42,040] {taskinstance.py:1357} INFO - Starting attempt 1 of 2
[2023-04-21 11:05:42,040] {taskinstance.py:1358} INFO - 
--------------------------------------------------------------------------------
[2023-04-21 11:05:42,054] {taskinstance.py:1377} INFO - Executing <Task(BashOperator): bash_task_copy_data> on 2023-04-21 11:05:39.699725+00:00
[2023-04-21 11:05:42,057] {standard_task_runner.py:52} INFO - Started process 859 to run task
[2023-04-21 11:05:42,060] {standard_task_runner.py:79} INFO - Running: ['***', 'tasks', 'run', 'First_DAG', 'bash_task_copy_data', 'manual__2023-04-21T11:05:39.699725+00:00', '--job-id', '13', '--raw', '--subdir', 'DAGS_FOLDER/first.py', '--cfg-path', '/tmp/tmpfaud7lp4', '--error-file', '/tmp/tmp_c2rbvrf']
[2023-04-21 11:05:42,061] {standard_task_runner.py:80} INFO - Job 13: Subtask bash_task_copy_data
[2023-04-21 11:05:42,105] {task_command.py:369} INFO - Running <TaskInstance: First_DAG.bash_task_copy_data manual__2023-04-21T11:05:39.699725+00:00 [running]> on host 7b4a1553b0dc
[2023-04-21 11:05:42,166] {taskinstance.py:1571} INFO - Exporting the following env vars:
AIRFLOW_CTX_DAG_OWNER=***
AIRFLOW_CTX_DAG_ID=First_DAG
AIRFLOW_CTX_TASK_ID=bash_task_copy_data
AIRFLOW_CTX_EXECUTION_DATE=2023-04-21T11:05:39.699725+00:00
AIRFLOW_CTX_TRY_NUMBER=1
AIRFLOW_CTX_DAG_RUN_ID=manual__2023-04-21T11:05:39.699725+00:00
[2023-04-21 11:05:42,167] {subprocess.py:62} INFO - Tmp dir root location: 
 /tmp
[2023-04-21 11:05:42,168] {subprocess.py:74} INFO - Running command: ['bash', '-c', 'cp /opt/data/DATA_CENTER/DATA_LAKE/dataset_raw.txt /opt/data/DATA_CENTER/CLEAN_DATA']
[2023-04-21 11:05:42,175] {subprocess.py:85} INFO - Output:
[2023-04-21 11:05:42,177] {subprocess.py:92} INFO - cp: cannot stat '/opt/data/DATA_CENTER/DATA_LAKE/dataset_raw.txt': No such file or directory
[2023-04-21 11:05:42,178] {subprocess.py:96} INFO - Command exited with return code 1
[2023-04-21 11:05:42,190] {taskinstance.py:1889} ERROR - Task failed with exception
Traceback (most recent call last):
  File "/home/airflow/.local/lib/python3.7/site-packages/airflow/operators/bash.py", line 195, in execute
    f'Bash command failed. The command returned a non-zero exit code {result.exit_code}.'
airflow.exceptions.AirflowException: Bash command failed. The command returned a non-zero exit code 1.
[2023-04-21 11:05:42,194] {taskinstance.py:1400} INFO - Marking task as UP_FOR_RETRY. dag_id=First_DAG, task_id=bash_task_copy_data, execution_date=20230421T110539, start_date=20230421T110542, end_date=20230421T110542
[2023-04-21 11:05:42,205] {standard_task_runner.py:97} ERROR - Failed to execute job 13 for task bash_task_copy_data (Bash command failed. The command returned a non-zero exit code 1.; 859)
[2023-04-21 11:05:42,234] {local_task_job.py:156} INFO - Task exited with return code 1
[2023-04-21 11:05:42,270] {local_task_job.py:273} INFO - 0 downstream tasks scheduled from follow-on schedule check
