[2023-04-21 11:10:42,990] {taskinstance.py:1159} INFO - Dependencies all met for <TaskInstance: First_DAG.bash_task_copy_data manual__2023-04-21T11:05:39.699725+00:00 [queued]>
[2023-04-21 11:10:42,999] {taskinstance.py:1159} INFO - Dependencies all met for <TaskInstance: First_DAG.bash_task_copy_data manual__2023-04-21T11:05:39.699725+00:00 [queued]>
[2023-04-21 11:10:42,999] {taskinstance.py:1356} INFO - 
--------------------------------------------------------------------------------
[2023-04-21 11:10:43,000] {taskinstance.py:1357} INFO - Starting attempt 2 of 2
[2023-04-21 11:10:43,001] {taskinstance.py:1358} INFO - 
--------------------------------------------------------------------------------
[2023-04-21 11:10:43,015] {taskinstance.py:1377} INFO - Executing <Task(BashOperator): bash_task_copy_data> on 2023-04-21 11:05:39.699725+00:00
[2023-04-21 11:10:43,018] {standard_task_runner.py:52} INFO - Started process 1105 to run task
[2023-04-21 11:10:43,020] {standard_task_runner.py:79} INFO - Running: ['***', 'tasks', 'run', 'First_DAG', 'bash_task_copy_data', 'manual__2023-04-21T11:05:39.699725+00:00', '--job-id', '17', '--raw', '--subdir', 'DAGS_FOLDER/first.py', '--cfg-path', '/tmp/tmp_492ytwn', '--error-file', '/tmp/tmplnqnmxy3']
[2023-04-21 11:10:43,021] {standard_task_runner.py:80} INFO - Job 17: Subtask bash_task_copy_data
[2023-04-21 11:10:43,065] {task_command.py:369} INFO - Running <TaskInstance: First_DAG.bash_task_copy_data manual__2023-04-21T11:05:39.699725+00:00 [running]> on host 7b4a1553b0dc
[2023-04-21 11:10:43,127] {taskinstance.py:1571} INFO - Exporting the following env vars:
AIRFLOW_CTX_DAG_OWNER=***
AIRFLOW_CTX_DAG_ID=First_DAG
AIRFLOW_CTX_TASK_ID=bash_task_copy_data
AIRFLOW_CTX_EXECUTION_DATE=2023-04-21T11:05:39.699725+00:00
AIRFLOW_CTX_TRY_NUMBER=2
AIRFLOW_CTX_DAG_RUN_ID=manual__2023-04-21T11:05:39.699725+00:00
[2023-04-21 11:10:43,128] {subprocess.py:62} INFO - Tmp dir root location: 
 /tmp
[2023-04-21 11:10:43,129] {subprocess.py:74} INFO - Running command: ['bash', '-c', 'cp /opt/***/data/DATA_CENTER/DATA_LAKE/dataset_raw.txt /opt/***/data/DATA_CENTER/CLEAN_DATA']
[2023-04-21 11:10:43,136] {subprocess.py:85} INFO - Output:
[2023-04-21 11:10:43,143] {subprocess.py:92} INFO - cp: cannot stat '/opt/***/data/DATA_CENTER/DATA_LAKE/dataset_raw.txt': No such file or directory
[2023-04-21 11:10:43,144] {subprocess.py:96} INFO - Command exited with return code 1
[2023-04-21 11:10:43,156] {taskinstance.py:1889} ERROR - Task failed with exception
Traceback (most recent call last):
  File "/home/airflow/.local/lib/python3.7/site-packages/airflow/operators/bash.py", line 195, in execute
    f'Bash command failed. The command returned a non-zero exit code {result.exit_code}.'
airflow.exceptions.AirflowException: Bash command failed. The command returned a non-zero exit code 1.
[2023-04-21 11:10:43,159] {taskinstance.py:1400} INFO - Marking task as FAILED. dag_id=First_DAG, task_id=bash_task_copy_data, execution_date=20230421T110539, start_date=20230421T111042, end_date=20230421T111043
[2023-04-21 11:10:43,170] {standard_task_runner.py:97} ERROR - Failed to execute job 17 for task bash_task_copy_data (Bash command failed. The command returned a non-zero exit code 1.; 1105)
[2023-04-21 11:10:43,194] {local_task_job.py:156} INFO - Task exited with return code 1
[2023-04-21 11:10:43,228] {local_task_job.py:273} INFO - 0 downstream tasks scheduled from follow-on schedule check
