[2023-04-22 09:19:19,830] {taskinstance.py:1159} INFO - Dependencies all met for <TaskInstance: market_data_alphavantage_dag.get_market_data scheduled__2023-04-21T00:00:00+00:00 [queued]>
[2023-04-22 09:19:19,837] {taskinstance.py:1159} INFO - Dependencies all met for <TaskInstance: market_data_alphavantage_dag.get_market_data scheduled__2023-04-21T00:00:00+00:00 [queued]>
[2023-04-22 09:19:19,837] {taskinstance.py:1356} INFO - 
--------------------------------------------------------------------------------
[2023-04-22 09:19:19,839] {taskinstance.py:1357} INFO - Starting attempt 1 of 2
[2023-04-22 09:19:19,839] {taskinstance.py:1358} INFO - 
--------------------------------------------------------------------------------
[2023-04-22 09:19:19,852] {taskinstance.py:1377} INFO - Executing <Task(PythonOperator): get_market_data> on 2023-04-21 00:00:00+00:00
[2023-04-22 09:19:19,856] {standard_task_runner.py:52} INFO - Started process 118 to run task
[2023-04-22 09:19:19,858] {standard_task_runner.py:79} INFO - Running: ['***', 'tasks', 'run', 'market_data_alphavantage_dag', 'get_market_data', 'scheduled__2023-04-21T00:00:00+00:00', '--job-id', '23', '--raw', '--subdir', 'DAGS_FOLDER/third.py', '--cfg-path', '/tmp/tmp0iqwf8z8', '--error-file', '/tmp/tmpholbntyg']
[2023-04-22 09:19:19,859] {standard_task_runner.py:80} INFO - Job 23: Subtask get_market_data
[2023-04-22 09:19:19,905] {task_command.py:369} INFO - Running <TaskInstance: market_data_alphavantage_dag.get_market_data scheduled__2023-04-21T00:00:00+00:00 [running]> on host 877f888c9ae3
[2023-04-22 09:19:19,965] {taskinstance.py:1571} INFO - Exporting the following env vars:
AIRFLOW_CTX_DAG_OWNER=***
AIRFLOW_CTX_DAG_ID=market_data_alphavantage_dag
AIRFLOW_CTX_TASK_ID=get_market_data
AIRFLOW_CTX_EXECUTION_DATE=2023-04-21T00:00:00+00:00
AIRFLOW_CTX_TRY_NUMBER=1
AIRFLOW_CTX_DAG_RUN_ID=scheduled__2023-04-21T00:00:00+00:00
[2023-04-22 09:19:19,967] {taskinstance.py:1889} ERROR - Task failed with exception
Traceback (most recent call last):
  File "/home/airflow/.local/lib/python3.7/site-packages/airflow/operators/python.py", line 171, in execute
    return_value = self.execute_callable()
  File "/home/airflow/.local/lib/python3.7/site-packages/airflow/operators/python.py", line 189, in execute_callable
    return self.python_callable(*self.op_args, **self.op_kwargs)
  File "/opt/airflow/dags/third.py", line 20, in get_data
    ticker= kwargs['ticker']
KeyError: 'ticker'
[2023-04-22 09:19:19,980] {taskinstance.py:1400} INFO - Marking task as UP_FOR_RETRY. dag_id=market_data_alphavantage_dag, task_id=get_market_data, execution_date=20230421T000000, start_date=20230422T091919, end_date=20230422T091919
[2023-04-22 09:19:19,991] {standard_task_runner.py:97} ERROR - Failed to execute job 23 for task get_market_data ('ticker'; 118)
[2023-04-22 09:19:20,032] {local_task_job.py:156} INFO - Task exited with return code 1
[2023-04-22 09:19:20,065] {local_task_job.py:273} INFO - 0 downstream tasks scheduled from follow-on schedule check
