[2023-04-21 10:53:36,954] {taskinstance.py:1159} INFO - Dependencies all met for <TaskInstance: First_DAG.bash_task_copy_data manual__2023-04-21T10:53:35.017906+00:00 [queued]>
[2023-04-21 10:53:36,962] {taskinstance.py:1159} INFO - Dependencies all met for <TaskInstance: First_DAG.bash_task_copy_data manual__2023-04-21T10:53:35.017906+00:00 [queued]>
[2023-04-21 10:53:36,963] {taskinstance.py:1356} INFO - 
--------------------------------------------------------------------------------
[2023-04-21 10:53:36,963] {taskinstance.py:1357} INFO - Starting attempt 1 of 2
[2023-04-21 10:53:36,964] {taskinstance.py:1358} INFO - 
--------------------------------------------------------------------------------
[2023-04-21 10:53:36,978] {taskinstance.py:1377} INFO - Executing <Task(BashOperator): bash_task_copy_data> on 2023-04-21 10:53:35.017906+00:00
[2023-04-21 10:53:36,983] {standard_task_runner.py:52} INFO - Started process 259 to run task
[2023-04-21 10:53:36,985] {standard_task_runner.py:79} INFO - Running: ['***', 'tasks', 'run', 'First_DAG', 'bash_task_copy_data', 'manual__2023-04-21T10:53:35.017906+00:00', '--job-id', '6', '--raw', '--subdir', 'DAGS_FOLDER/first.py', '--cfg-path', '/tmp/tmp2mjpui33', '--error-file', '/tmp/tmp0jnkklu_']
[2023-04-21 10:53:36,986] {standard_task_runner.py:80} INFO - Job 6: Subtask bash_task_copy_data
[2023-04-21 10:53:37,033] {task_command.py:369} INFO - Running <TaskInstance: First_DAG.bash_task_copy_data manual__2023-04-21T10:53:35.017906+00:00 [running]> on host 7b4a1553b0dc
[2023-04-21 10:53:37,095] {taskinstance.py:1571} INFO - Exporting the following env vars:
AIRFLOW_CTX_DAG_OWNER=***
AIRFLOW_CTX_DAG_ID=First_DAG
AIRFLOW_CTX_TASK_ID=bash_task_copy_data
AIRFLOW_CTX_EXECUTION_DATE=2023-04-21T10:53:35.017906+00:00
AIRFLOW_CTX_TRY_NUMBER=1
AIRFLOW_CTX_DAG_RUN_ID=manual__2023-04-21T10:53:35.017906+00:00
[2023-04-21 10:53:37,096] {subprocess.py:62} INFO - Tmp dir root location: 
 /tmp
[2023-04-21 10:53:37,097] {subprocess.py:74} INFO - Running command: ['bash', '-c', 'cp ./data/DATA_CENTER/DATA_LAKE/dataset_raw.txt ./data/DATA_CENTER/CLEAN_DATA']
[2023-04-21 10:53:37,105] {subprocess.py:85} INFO - Output:
[2023-04-21 10:53:37,107] {subprocess.py:92} INFO - cp: cannot stat './data/DATA_CENTER/DATA_LAKE/dataset_raw.txt': No such file or directory
[2023-04-21 10:53:37,108] {subprocess.py:96} INFO - Command exited with return code 1
[2023-04-21 10:53:37,119] {taskinstance.py:1889} ERROR - Task failed with exception
Traceback (most recent call last):
  File "/home/airflow/.local/lib/python3.7/site-packages/airflow/operators/bash.py", line 195, in execute
    f'Bash command failed. The command returned a non-zero exit code {result.exit_code}.'
airflow.exceptions.AirflowException: Bash command failed. The command returned a non-zero exit code 1.
[2023-04-21 10:53:37,123] {taskinstance.py:1400} INFO - Marking task as UP_FOR_RETRY. dag_id=First_DAG, task_id=bash_task_copy_data, execution_date=20230421T105335, start_date=20230421T105336, end_date=20230421T105337
[2023-04-21 10:53:37,134] {standard_task_runner.py:97} ERROR - Failed to execute job 6 for task bash_task_copy_data (Bash command failed. The command returned a non-zero exit code 1.; 259)
[2023-04-21 10:53:37,159] {local_task_job.py:156} INFO - Task exited with return code 1
[2023-04-21 10:53:37,191] {local_task_job.py:273} INFO - 0 downstream tasks scheduled from follow-on schedule check
