[2023-04-22 09:29:52,361] {taskinstance.py:1159} INFO - Dependencies all met for <TaskInstance: market_data_alphavantage_dag.clean_market_data manual__2023-04-22T09:24:35.837796+00:00 [queued]>
[2023-04-22 09:29:52,369] {taskinstance.py:1159} INFO - Dependencies all met for <TaskInstance: market_data_alphavantage_dag.clean_market_data manual__2023-04-22T09:24:35.837796+00:00 [queued]>
[2023-04-22 09:29:52,369] {taskinstance.py:1356} INFO - 
--------------------------------------------------------------------------------
[2023-04-22 09:29:52,370] {taskinstance.py:1357} INFO - Starting attempt 1 of 2
[2023-04-22 09:29:52,371] {taskinstance.py:1358} INFO - 
--------------------------------------------------------------------------------
[2023-04-22 09:29:52,385] {taskinstance.py:1377} INFO - Executing <Task(PythonOperator): clean_market_data> on 2023-04-22 09:24:35.837796+00:00
[2023-04-22 09:29:52,389] {standard_task_runner.py:52} INFO - Started process 642 to run task
[2023-04-22 09:29:52,392] {standard_task_runner.py:79} INFO - Running: ['***', 'tasks', 'run', 'market_data_alphavantage_dag', 'clean_market_data', 'manual__2023-04-22T09:24:35.837796+00:00', '--job-id', '30', '--raw', '--subdir', 'DAGS_FOLDER/third.py', '--cfg-path', '/tmp/tmp52xtq4qc', '--error-file', '/tmp/tmpkep36oxk']
[2023-04-22 09:29:52,393] {standard_task_runner.py:80} INFO - Job 30: Subtask clean_market_data
[2023-04-22 09:29:52,439] {task_command.py:369} INFO - Running <TaskInstance: market_data_alphavantage_dag.clean_market_data manual__2023-04-22T09:24:35.837796+00:00 [running]> on host 877f888c9ae3
[2023-04-22 09:29:52,505] {taskinstance.py:1571} INFO - Exporting the following env vars:
AIRFLOW_CTX_DAG_OWNER=***
AIRFLOW_CTX_DAG_ID=market_data_alphavantage_dag
AIRFLOW_CTX_TASK_ID=clean_market_data
AIRFLOW_CTX_EXECUTION_DATE=2023-04-22T09:24:35.837796+00:00
AIRFLOW_CTX_TRY_NUMBER=1
AIRFLOW_CTX_DAG_RUN_ID=manual__2023-04-22T09:24:35.837796+00:00
[2023-04-22 09:29:52,507] {taskinstance.py:1889} ERROR - Task failed with exception
Traceback (most recent call last):
  File "/home/airflow/.local/lib/python3.7/site-packages/airflow/operators/python.py", line 171, in execute
    return_value = self.execute_callable()
  File "/home/airflow/.local/lib/python3.7/site-packages/airflow/operators/python.py", line 189, in execute_callable
    return self.python_callable(*self.op_args, **self.op_kwargs)
  File "/opt/airflow/dags/third.py", line 38, in clean_market_data
    latest = np.max([float(file.split("_")[-1]) for file in os.listdir(read_path)if tick in file])
FileNotFoundError: [Errno 2] No such file or directory: '/opt/data/DATA_CENTER/DATA_LAKE'
[2023-04-22 09:29:52,520] {taskinstance.py:1400} INFO - Marking task as UP_FOR_RETRY. dag_id=market_data_alphavantage_dag, task_id=clean_market_data, execution_date=20230422T092435, start_date=20230422T092952, end_date=20230422T092952
[2023-04-22 09:29:52,530] {standard_task_runner.py:97} ERROR - Failed to execute job 30 for task clean_market_data ([Errno 2] No such file or directory: '/opt/data/DATA_CENTER/DATA_LAKE'; 642)
[2023-04-22 09:29:52,565] {local_task_job.py:156} INFO - Task exited with return code 1
[2023-04-22 09:29:52,593] {local_task_job.py:273} INFO - 0 downstream tasks scheduled from follow-on schedule check
