[2023-04-22 09:33:04,983] {taskinstance.py:1159} INFO - Dependencies all met for <TaskInstance: market_data_alphavantage_dag.clean_market_data manual__2023-04-22T09:24:35.837796+00:00 [queued]>
[2023-04-22 09:33:04,994] {taskinstance.py:1159} INFO - Dependencies all met for <TaskInstance: market_data_alphavantage_dag.clean_market_data manual__2023-04-22T09:24:35.837796+00:00 [queued]>
[2023-04-22 09:33:04,995] {taskinstance.py:1356} INFO - 
--------------------------------------------------------------------------------
[2023-04-22 09:33:04,996] {taskinstance.py:1357} INFO - Starting attempt 2 of 2
[2023-04-22 09:33:04,997] {taskinstance.py:1358} INFO - 
--------------------------------------------------------------------------------
[2023-04-22 09:33:05,015] {taskinstance.py:1377} INFO - Executing <Task(PythonOperator): clean_market_data> on 2023-04-22 09:24:35.837796+00:00
[2023-04-22 09:33:05,022] {standard_task_runner.py:52} INFO - Started process 804 to run task
[2023-04-22 09:33:05,026] {standard_task_runner.py:79} INFO - Running: ['***', 'tasks', 'run', 'market_data_alphavantage_dag', 'clean_market_data', 'manual__2023-04-22T09:24:35.837796+00:00', '--job-id', '33', '--raw', '--subdir', 'DAGS_FOLDER/third.py', '--cfg-path', '/tmp/tmpuphr02cl', '--error-file', '/tmp/tmp2nz_y95_']
[2023-04-22 09:33:05,027] {standard_task_runner.py:80} INFO - Job 33: Subtask clean_market_data
[2023-04-22 09:33:05,088] {task_command.py:369} INFO - Running <TaskInstance: market_data_alphavantage_dag.clean_market_data manual__2023-04-22T09:24:35.837796+00:00 [running]> on host 877f888c9ae3
[2023-04-22 09:33:05,177] {taskinstance.py:1571} INFO - Exporting the following env vars:
AIRFLOW_CTX_DAG_OWNER=***
AIRFLOW_CTX_DAG_ID=market_data_alphavantage_dag
AIRFLOW_CTX_TASK_ID=clean_market_data
AIRFLOW_CTX_EXECUTION_DATE=2023-04-22T09:24:35.837796+00:00
AIRFLOW_CTX_TRY_NUMBER=2
AIRFLOW_CTX_DAG_RUN_ID=manual__2023-04-22T09:24:35.837796+00:00
[2023-04-22 09:33:05,184] {taskinstance.py:1889} ERROR - Task failed with exception
Traceback (most recent call last):
  File "/home/airflow/.local/lib/python3.7/site-packages/airflow/operators/python.py", line 171, in execute
    return_value = self.execute_callable()
  File "/home/airflow/.local/lib/python3.7/site-packages/airflow/operators/python.py", line 189, in execute_callable
    return self.python_callable(*self.op_args, **self.op_kwargs)
  File "/opt/airflow/dags/third.py", line 39, in clean_market_data
    latest = np.max([float(file.split("_")[-1]) for file in os.listdir(read_path)if tick in file])
  File "<__array_function__ internals>", line 6, in amax
  File "/home/airflow/.local/lib/python3.7/site-packages/numpy/core/fromnumeric.py", line 2755, in amax
    keepdims=keepdims, initial=initial, where=where)
  File "/home/airflow/.local/lib/python3.7/site-packages/numpy/core/fromnumeric.py", line 86, in _wrapreduction
    return ufunc.reduce(obj, axis, dtype, out, **passkwargs)
ValueError: zero-size array to reduction operation maximum which has no identity
[2023-04-22 09:33:05,197] {taskinstance.py:1400} INFO - Marking task as FAILED. dag_id=market_data_alphavantage_dag, task_id=clean_market_data, execution_date=20230422T092435, start_date=20230422T093304, end_date=20230422T093305
[2023-04-22 09:33:05,210] {standard_task_runner.py:97} ERROR - Failed to execute job 33 for task clean_market_data (zero-size array to reduction operation maximum which has no identity; 804)
[2023-04-22 09:33:05,239] {local_task_job.py:156} INFO - Task exited with return code 1
[2023-04-22 09:33:05,266] {local_task_job.py:273} INFO - 0 downstream tasks scheduled from follow-on schedule check
