[2023-04-22 09:20:04,049] {taskinstance.py:1159} INFO - Dependencies all met for <TaskInstance: market_data_alphavantage_dag.get_market_data manual__2023-04-22T09:20:02.858139+00:00 [queued]>
[2023-04-22 09:20:04,058] {taskinstance.py:1159} INFO - Dependencies all met for <TaskInstance: market_data_alphavantage_dag.get_market_data manual__2023-04-22T09:20:02.858139+00:00 [queued]>
[2023-04-22 09:20:04,058] {taskinstance.py:1356} INFO - 
--------------------------------------------------------------------------------
[2023-04-22 09:20:04,059] {taskinstance.py:1357} INFO - Starting attempt 1 of 2
[2023-04-22 09:20:04,059] {taskinstance.py:1358} INFO - 
--------------------------------------------------------------------------------
[2023-04-22 09:20:04,075] {taskinstance.py:1377} INFO - Executing <Task(PythonOperator): get_market_data> on 2023-04-22 09:20:02.858139+00:00
[2023-04-22 09:20:04,079] {standard_task_runner.py:52} INFO - Started process 157 to run task
[2023-04-22 09:20:04,082] {standard_task_runner.py:79} INFO - Running: ['***', 'tasks', 'run', 'market_data_alphavantage_dag', 'get_market_data', 'manual__2023-04-22T09:20:02.858139+00:00', '--job-id', '24', '--raw', '--subdir', 'DAGS_FOLDER/third.py', '--cfg-path', '/tmp/tmp4en2flza', '--error-file', '/tmp/tmp0rzwyq5r']
[2023-04-22 09:20:04,083] {standard_task_runner.py:80} INFO - Job 24: Subtask get_market_data
[2023-04-22 09:20:04,145] {task_command.py:369} INFO - Running <TaskInstance: market_data_alphavantage_dag.get_market_data manual__2023-04-22T09:20:02.858139+00:00 [running]> on host 877f888c9ae3
[2023-04-22 09:20:04,219] {taskinstance.py:1571} INFO - Exporting the following env vars:
AIRFLOW_CTX_DAG_OWNER=***
AIRFLOW_CTX_DAG_ID=market_data_alphavantage_dag
AIRFLOW_CTX_TASK_ID=get_market_data
AIRFLOW_CTX_EXECUTION_DATE=2023-04-22T09:20:02.858139+00:00
AIRFLOW_CTX_TRY_NUMBER=1
AIRFLOW_CTX_DAG_RUN_ID=manual__2023-04-22T09:20:02.858139+00:00
[2023-04-22 09:20:04,220] {taskinstance.py:1889} ERROR - Task failed with exception
Traceback (most recent call last):
  File "/home/airflow/.local/lib/python3.7/site-packages/airflow/operators/python.py", line 171, in execute
    return_value = self.execute_callable()
  File "/home/airflow/.local/lib/python3.7/site-packages/airflow/operators/python.py", line 189, in execute_callable
    return self.python_callable(*self.op_args, **self.op_kwargs)
  File "/opt/airflow/dags/third.py", line 20, in get_data
    ticker= kwargs['ticker']
KeyError: 'ticker'
[2023-04-22 09:20:04,234] {taskinstance.py:1400} INFO - Marking task as UP_FOR_RETRY. dag_id=market_data_alphavantage_dag, task_id=get_market_data, execution_date=20230422T092002, start_date=20230422T092004, end_date=20230422T092004
[2023-04-22 09:20:04,247] {standard_task_runner.py:97} ERROR - Failed to execute job 24 for task get_market_data ('ticker'; 157)
[2023-04-22 09:20:04,295] {local_task_job.py:156} INFO - Task exited with return code 1
[2023-04-22 09:20:04,334] {local_task_job.py:273} INFO - 0 downstream tasks scheduled from follow-on schedule check
