[2023-04-22 09:38:36,717] {taskinstance.py:1159} INFO - Dependencies all met for <TaskInstance: market_data_alphavantage_dag.get_market_data manual__2023-04-22T09:37:23.939032+00:00 [queued]>
[2023-04-22 09:38:36,724] {taskinstance.py:1159} INFO - Dependencies all met for <TaskInstance: market_data_alphavantage_dag.get_market_data manual__2023-04-22T09:37:23.939032+00:00 [queued]>
[2023-04-22 09:38:36,725] {taskinstance.py:1356} INFO - 
--------------------------------------------------------------------------------
[2023-04-22 09:38:36,725] {taskinstance.py:1357} INFO - Starting attempt 2 of 2
[2023-04-22 09:38:36,726] {taskinstance.py:1358} INFO - 
--------------------------------------------------------------------------------
[2023-04-22 09:38:36,738] {taskinstance.py:1377} INFO - Executing <Task(PythonOperator): get_market_data> on 2023-04-22 09:37:23.939032+00:00
[2023-04-22 09:38:36,743] {standard_task_runner.py:52} INFO - Started process 1084 to run task
[2023-04-22 09:38:36,745] {standard_task_runner.py:79} INFO - Running: ['***', 'tasks', 'run', 'market_data_alphavantage_dag', 'get_market_data', 'manual__2023-04-22T09:37:23.939032+00:00', '--job-id', '39', '--raw', '--subdir', 'DAGS_FOLDER/third.py', '--cfg-path', '/tmp/tmpzafrerg4', '--error-file', '/tmp/tmpxebwpd62']
[2023-04-22 09:38:36,746] {standard_task_runner.py:80} INFO - Job 39: Subtask get_market_data
[2023-04-22 09:38:36,792] {task_command.py:369} INFO - Running <TaskInstance: market_data_alphavantage_dag.get_market_data manual__2023-04-22T09:37:23.939032+00:00 [running]> on host 877f888c9ae3
[2023-04-22 09:38:36,852] {taskinstance.py:1571} INFO - Exporting the following env vars:
AIRFLOW_CTX_DAG_OWNER=***
AIRFLOW_CTX_DAG_ID=market_data_alphavantage_dag
AIRFLOW_CTX_TASK_ID=get_market_data
AIRFLOW_CTX_EXECUTION_DATE=2023-04-22T09:37:23.939032+00:00
AIRFLOW_CTX_TRY_NUMBER=2
AIRFLOW_CTX_DAG_RUN_ID=manual__2023-04-22T09:37:23.939032+00:00
[2023-04-22 09:38:36,853] {logging_mixin.py:115} INFO - IBM
[2023-04-22 09:38:36,854] {logging_mixin.py:115} INFO - https://www.alphavantage.co/query?function=TIME_SERIES_INTRADAY&symbol=IBM&interval=5min&apikey=AZQ6QOXNR3NDY4N2
[2023-04-22 09:38:46,865] {taskinstance.py:1889} ERROR - Task failed with exception
Traceback (most recent call last):
  File "/home/airflow/.local/lib/python3.7/site-packages/urllib3/connection.py", line 175, in _new_conn
    (self._dns_host, self.port), self.timeout, **extra_kw
  File "/home/airflow/.local/lib/python3.7/site-packages/urllib3/util/connection.py", line 72, in create_connection
    for res in socket.getaddrinfo(host, port, family, socket.SOCK_STREAM):
  File "/usr/local/lib/python3.7/socket.py", line 752, in getaddrinfo
    for res in _socket.getaddrinfo(host, port, family, type, proto, flags):
socket.gaierror: [Errno -3] Temporary failure in name resolution

During handling of the above exception, another exception occurred:

Traceback (most recent call last):
  File "/home/airflow/.local/lib/python3.7/site-packages/urllib3/connectionpool.py", line 710, in urlopen
    chunked=chunked,
  File "/home/airflow/.local/lib/python3.7/site-packages/urllib3/connectionpool.py", line 386, in _make_request
    self._validate_conn(conn)
  File "/home/airflow/.local/lib/python3.7/site-packages/urllib3/connectionpool.py", line 1040, in _validate_conn
    conn.connect()
  File "/home/airflow/.local/lib/python3.7/site-packages/urllib3/connection.py", line 358, in connect
    self.sock = conn = self._new_conn()
  File "/home/airflow/.local/lib/python3.7/site-packages/urllib3/connection.py", line 187, in _new_conn
    self, "Failed to establish a new connection: %s" % e
urllib3.exceptions.NewConnectionError: <urllib3.connection.HTTPSConnection object at 0x7fda9f424b10>: Failed to establish a new connection: [Errno -3] Temporary failure in name resolution

During handling of the above exception, another exception occurred:

Traceback (most recent call last):
  File "/home/airflow/.local/lib/python3.7/site-packages/requests/adapters.py", line 450, in send
    timeout=timeout
  File "/home/airflow/.local/lib/python3.7/site-packages/urllib3/connectionpool.py", line 786, in urlopen
    method, url, error=e, _pool=self, _stacktrace=sys.exc_info()[2]
  File "/home/airflow/.local/lib/python3.7/site-packages/urllib3/util/retry.py", line 592, in increment
    raise MaxRetryError(_pool, url, error or ResponseError(cause))
urllib3.exceptions.MaxRetryError: HTTPSConnectionPool(host='www.alphavantage.co', port=443): Max retries exceeded with url: /query?function=TIME_SERIES_INTRADAY&symbol=IBM&interval=5min&apikey=AZQ6QOXNR3NDY4N2 (Caused by NewConnectionError('<urllib3.connection.HTTPSConnection object at 0x7fda9f424b10>: Failed to establish a new connection: [Errno -3] Temporary failure in name resolution'))

During handling of the above exception, another exception occurred:

Traceback (most recent call last):
  File "/home/airflow/.local/lib/python3.7/site-packages/airflow/operators/python.py", line 171, in execute
    return_value = self.execute_callable()
  File "/home/airflow/.local/lib/python3.7/site-packages/airflow/operators/python.py", line 189, in execute_callable
    return self.python_callable(*self.op_args, **self.op_kwargs)
  File "/opt/airflow/dags/third.py", line 25, in get_data
    r = requests.get(url)
  File "/home/airflow/.local/lib/python3.7/site-packages/requests/api.py", line 75, in get
    return request('get', url, params=params, **kwargs)
  File "/home/airflow/.local/lib/python3.7/site-packages/requests/api.py", line 61, in request
    return session.request(method=method, url=url, **kwargs)
  File "/home/airflow/.local/lib/python3.7/site-packages/requests/sessions.py", line 529, in request
    resp = self.send(prep, **send_kwargs)
  File "/home/airflow/.local/lib/python3.7/site-packages/requests/sessions.py", line 645, in send
    r = adapter.send(request, **kwargs)
  File "/home/airflow/.local/lib/python3.7/site-packages/requests/adapters.py", line 519, in send
    raise ConnectionError(e, request=request)
requests.exceptions.ConnectionError: HTTPSConnectionPool(host='www.alphavantage.co', port=443): Max retries exceeded with url: /query?function=TIME_SERIES_INTRADAY&symbol=IBM&interval=5min&apikey=AZQ6QOXNR3NDY4N2 (Caused by NewConnectionError('<urllib3.connection.HTTPSConnection object at 0x7fda9f424b10>: Failed to establish a new connection: [Errno -3] Temporary failure in name resolution'))
[2023-04-22 09:38:46,878] {taskinstance.py:1400} INFO - Marking task as FAILED. dag_id=market_data_alphavantage_dag, task_id=get_market_data, execution_date=20230422T093723, start_date=20230422T093836, end_date=20230422T093846
[2023-04-22 09:38:46,889] {standard_task_runner.py:97} ERROR - Failed to execute job 39 for task get_market_data (HTTPSConnectionPool(host='www.alphavantage.co', port=443): Max retries exceeded with url: /query?function=TIME_SERIES_INTRADAY&symbol=IBM&interval=5min&apikey=AZQ6QOXNR3NDY4N2 (Caused by NewConnectionError('<urllib3.connection.HTTPSConnection object at 0x7fda9f424b10>: Failed to establish a new connection: [Errno -3] Temporary failure in name resolution')); 1084)
[2023-04-22 09:38:46,927] {local_task_job.py:156} INFO - Task exited with return code 1
[2023-04-22 09:38:46,957] {local_task_job.py:273} INFO - 0 downstream tasks scheduled from follow-on schedule check
