[2023-04-21 10:51:22,852] {taskinstance.py:1159} INFO - Dependencies all met for <TaskInstance: First_DAG.bash_task_copy_data manual__2023-04-21T10:51:20.228530+00:00 [queued]>
[2023-04-21 10:51:22,858] {taskinstance.py:1159} INFO - Dependencies all met for <TaskInstance: First_DAG.bash_task_copy_data manual__2023-04-21T10:51:20.228530+00:00 [queued]>
[2023-04-21 10:51:22,859] {taskinstance.py:1356} INFO - 
--------------------------------------------------------------------------------
[2023-04-21 10:51:22,859] {taskinstance.py:1357} INFO - Starting attempt 1 of 2
[2023-04-21 10:51:22,860] {taskinstance.py:1358} INFO - 
--------------------------------------------------------------------------------
[2023-04-21 10:51:22,872] {taskinstance.py:1377} INFO - Executing <Task(BashOperator): bash_task_copy_data> on 2023-04-21 10:51:20.228530+00:00
[2023-04-21 10:51:22,875] {standard_task_runner.py:52} INFO - Started process 145 to run task
[2023-04-21 10:51:22,877] {standard_task_runner.py:79} INFO - Running: ['***', 'tasks', 'run', 'First_DAG', 'bash_task_copy_data', 'manual__2023-04-21T10:51:20.228530+00:00', '--job-id', '4', '--raw', '--subdir', 'DAGS_FOLDER/first.py', '--cfg-path', '/tmp/tmpqyhexd38', '--error-file', '/tmp/tmp4kdgop_w']
[2023-04-21 10:51:22,878] {standard_task_runner.py:80} INFO - Job 4: Subtask bash_task_copy_data
[2023-04-21 10:51:22,918] {task_command.py:369} INFO - Running <TaskInstance: First_DAG.bash_task_copy_data manual__2023-04-21T10:51:20.228530+00:00 [running]> on host 7b4a1553b0dc
[2023-04-21 10:51:22,971] {taskinstance.py:1571} INFO - Exporting the following env vars:
AIRFLOW_CTX_DAG_OWNER=***
AIRFLOW_CTX_DAG_ID=First_DAG
AIRFLOW_CTX_TASK_ID=bash_task_copy_data
AIRFLOW_CTX_EXECUTION_DATE=2023-04-21T10:51:20.228530+00:00
AIRFLOW_CTX_TRY_NUMBER=1
AIRFLOW_CTX_DAG_RUN_ID=manual__2023-04-21T10:51:20.228530+00:00
[2023-04-21 10:51:22,972] {subprocess.py:62} INFO - Tmp dir root location: 
 /tmp
[2023-04-21 10:51:22,973] {subprocess.py:74} INFO - Running command: ['bash', '-c', 'cp /Users/glzma/onur/exercises/data/DATA_CENTER/DATA_LAKE/dataset_raw.txt /Users/glzma/onur/exercises/data/DATA_CENTER/CLEAN_DATA']
[2023-04-21 10:51:22,979] {subprocess.py:85} INFO - Output:
[2023-04-21 10:51:22,981] {subprocess.py:92} INFO - cp: cannot stat '/Users/glzma/onur/exercises/data/DATA_CENTER/DATA_LAKE/dataset_raw.txt': No such file or directory
[2023-04-21 10:51:22,982] {subprocess.py:96} INFO - Command exited with return code 1
[2023-04-21 10:51:22,993] {taskinstance.py:1889} ERROR - Task failed with exception
Traceback (most recent call last):
  File "/home/airflow/.local/lib/python3.7/site-packages/airflow/operators/bash.py", line 195, in execute
    f'Bash command failed. The command returned a non-zero exit code {result.exit_code}.'
airflow.exceptions.AirflowException: Bash command failed. The command returned a non-zero exit code 1.
[2023-04-21 10:51:22,995] {taskinstance.py:1400} INFO - Marking task as UP_FOR_RETRY. dag_id=First_DAG, task_id=bash_task_copy_data, execution_date=20230421T105120, start_date=20230421T105122, end_date=20230421T105122
[2023-04-21 10:51:23,005] {standard_task_runner.py:97} ERROR - Failed to execute job 4 for task bash_task_copy_data (Bash command failed. The command returned a non-zero exit code 1.; 145)
[2023-04-21 10:51:23,050] {local_task_job.py:156} INFO - Task exited with return code 1
[2023-04-21 10:51:23,080] {local_task_job.py:273} INFO - 0 downstream tasks scheduled from follow-on schedule check
