[2023-04-21 10:56:05,347] {taskinstance.py:1159} INFO - Dependencies all met for <TaskInstance: First_DAG.bash_task_copy_data manual__2023-04-21T10:56:03.262453+00:00 [queued]>
[2023-04-21 10:56:05,355] {taskinstance.py:1159} INFO - Dependencies all met for <TaskInstance: First_DAG.bash_task_copy_data manual__2023-04-21T10:56:03.262453+00:00 [queued]>
[2023-04-21 10:56:05,355] {taskinstance.py:1356} INFO - 
--------------------------------------------------------------------------------
[2023-04-21 10:56:05,356] {taskinstance.py:1357} INFO - Starting attempt 1 of 2
[2023-04-21 10:56:05,357] {taskinstance.py:1358} INFO - 
--------------------------------------------------------------------------------
[2023-04-21 10:56:05,371] {taskinstance.py:1377} INFO - Executing <Task(BashOperator): bash_task_copy_data> on 2023-04-21 10:56:03.262453+00:00
[2023-04-21 10:56:05,374] {standard_task_runner.py:52} INFO - Started process 382 to run task
[2023-04-21 10:56:05,377] {standard_task_runner.py:79} INFO - Running: ['***', 'tasks', 'run', 'First_DAG', 'bash_task_copy_data', 'manual__2023-04-21T10:56:03.262453+00:00', '--job-id', '8', '--raw', '--subdir', 'DAGS_FOLDER/first.py', '--cfg-path', '/tmp/tmptj3umdn1', '--error-file', '/tmp/tmpqfe_uh_r']
[2023-04-21 10:56:05,378] {standard_task_runner.py:80} INFO - Job 8: Subtask bash_task_copy_data
[2023-04-21 10:56:05,423] {task_command.py:369} INFO - Running <TaskInstance: First_DAG.bash_task_copy_data manual__2023-04-21T10:56:03.262453+00:00 [running]> on host 7b4a1553b0dc
[2023-04-21 10:56:05,485] {taskinstance.py:1571} INFO - Exporting the following env vars:
AIRFLOW_CTX_DAG_OWNER=***
AIRFLOW_CTX_DAG_ID=First_DAG
AIRFLOW_CTX_TASK_ID=bash_task_copy_data
AIRFLOW_CTX_EXECUTION_DATE=2023-04-21T10:56:03.262453+00:00
AIRFLOW_CTX_TRY_NUMBER=1
AIRFLOW_CTX_DAG_RUN_ID=manual__2023-04-21T10:56:03.262453+00:00
[2023-04-21 10:56:05,486] {subprocess.py:62} INFO - Tmp dir root location: 
 /tmp
[2023-04-21 10:56:05,487] {subprocess.py:74} INFO - Running command: ['bash', '-c', 'cp /data/DATA_CENTER/DATA_LAKE/dataset_raw.txt /data/DATA_CENTER/CLEAN_DATA']
[2023-04-21 10:56:05,494] {subprocess.py:85} INFO - Output:
[2023-04-21 10:56:05,497] {subprocess.py:92} INFO - cp: cannot stat '/data/DATA_CENTER/DATA_LAKE/dataset_raw.txt': No such file or directory
[2023-04-21 10:56:05,497] {subprocess.py:96} INFO - Command exited with return code 1
[2023-04-21 10:56:05,511] {taskinstance.py:1889} ERROR - Task failed with exception
Traceback (most recent call last):
  File "/home/airflow/.local/lib/python3.7/site-packages/airflow/operators/bash.py", line 195, in execute
    f'Bash command failed. The command returned a non-zero exit code {result.exit_code}.'
airflow.exceptions.AirflowException: Bash command failed. The command returned a non-zero exit code 1.
[2023-04-21 10:56:05,514] {taskinstance.py:1400} INFO - Marking task as UP_FOR_RETRY. dag_id=First_DAG, task_id=bash_task_copy_data, execution_date=20230421T105603, start_date=20230421T105605, end_date=20230421T105605
[2023-04-21 10:56:05,527] {standard_task_runner.py:97} ERROR - Failed to execute job 8 for task bash_task_copy_data (Bash command failed. The command returned a non-zero exit code 1.; 382)
[2023-04-21 10:56:05,550] {local_task_job.py:156} INFO - Task exited with return code 1
[2023-04-21 10:56:05,582] {local_task_job.py:273} INFO - 0 downstream tasks scheduled from follow-on schedule check
