[2023-04-22 09:38:39,647] {taskinstance.py:1159} INFO - Dependencies all met for <TaskInstance: market_data_alphavantage_dag.clean_market_data manual__2023-04-22T09:36:20.516292+00:00 [queued]>
[2023-04-22 09:38:39,654] {taskinstance.py:1159} INFO - Dependencies all met for <TaskInstance: market_data_alphavantage_dag.clean_market_data manual__2023-04-22T09:36:20.516292+00:00 [queued]>
[2023-04-22 09:38:39,654] {taskinstance.py:1356} INFO - 
--------------------------------------------------------------------------------
[2023-04-22 09:38:39,655] {taskinstance.py:1357} INFO - Starting attempt 2 of 2
[2023-04-22 09:38:39,656] {taskinstance.py:1358} INFO - 
--------------------------------------------------------------------------------
[2023-04-22 09:38:39,669] {taskinstance.py:1377} INFO - Executing <Task(PythonOperator): clean_market_data> on 2023-04-22 09:36:20.516292+00:00
[2023-04-22 09:38:39,673] {standard_task_runner.py:52} INFO - Started process 1087 to run task
[2023-04-22 09:38:39,676] {standard_task_runner.py:79} INFO - Running: ['***', 'tasks', 'run', 'market_data_alphavantage_dag', 'clean_market_data', 'manual__2023-04-22T09:36:20.516292+00:00', '--job-id', '40', '--raw', '--subdir', 'DAGS_FOLDER/third.py', '--cfg-path', '/tmp/tmpoungkbo_', '--error-file', '/tmp/tmpbh2hetgk']
[2023-04-22 09:38:39,677] {standard_task_runner.py:80} INFO - Job 40: Subtask clean_market_data
[2023-04-22 09:38:39,724] {task_command.py:369} INFO - Running <TaskInstance: market_data_alphavantage_dag.clean_market_data manual__2023-04-22T09:36:20.516292+00:00 [running]> on host 877f888c9ae3
[2023-04-22 09:38:39,791] {taskinstance.py:1571} INFO - Exporting the following env vars:
AIRFLOW_CTX_DAG_OWNER=***
AIRFLOW_CTX_DAG_ID=market_data_alphavantage_dag
AIRFLOW_CTX_TASK_ID=clean_market_data
AIRFLOW_CTX_EXECUTION_DATE=2023-04-22T09:36:20.516292+00:00
AIRFLOW_CTX_TRY_NUMBER=2
AIRFLOW_CTX_DAG_RUN_ID=manual__2023-04-22T09:36:20.516292+00:00
[2023-04-22 09:38:39,803] {taskinstance.py:1889} ERROR - Task failed with exception
Traceback (most recent call last):
  File "/home/airflow/.local/lib/python3.7/site-packages/airflow/operators/python.py", line 171, in execute
    return_value = self.execute_callable()
  File "/home/airflow/.local/lib/python3.7/site-packages/airflow/operators/python.py", line 189, in execute_callable
    return self.python_callable(*self.op_args, **self.op_kwargs)
  File "/opt/airflow/dags/third.py", line 43, in clean_market_data
    file=open(read_path+latest_file)
FileNotFoundError: [Errno 2] No such file or directory: '/opt/airflow/data/DATA_CENTER/DATA_LAKEstock_market_raw_data_I_1682156256.3001113'
[2023-04-22 09:38:39,814] {taskinstance.py:1400} INFO - Marking task as FAILED. dag_id=market_data_alphavantage_dag, task_id=clean_market_data, execution_date=20230422T093620, start_date=20230422T093839, end_date=20230422T093839
[2023-04-22 09:38:39,823] {standard_task_runner.py:97} ERROR - Failed to execute job 40 for task clean_market_data ([Errno 2] No such file or directory: '/opt/airflow/data/DATA_CENTER/DATA_LAKEstock_market_raw_data_I_1682156256.3001113'; 1087)
[2023-04-22 09:38:39,850] {local_task_job.py:156} INFO - Task exited with return code 1
[2023-04-22 09:38:39,876] {local_task_job.py:273} INFO - 0 downstream tasks scheduled from follow-on schedule check
