[2023-04-22 09:37:38,487] {taskinstance.py:1159} INFO - Dependencies all met for <TaskInstance: market_data_alphavantage_dag.clean_market_data manual__2023-04-22T09:36:20.516292+00:00 [queued]>
[2023-04-22 09:37:38,496] {taskinstance.py:1159} INFO - Dependencies all met for <TaskInstance: market_data_alphavantage_dag.clean_market_data manual__2023-04-22T09:36:20.516292+00:00 [queued]>
[2023-04-22 09:37:38,496] {taskinstance.py:1356} INFO - 
--------------------------------------------------------------------------------
[2023-04-22 09:37:38,498] {taskinstance.py:1357} INFO - Starting attempt 1 of 2
[2023-04-22 09:37:38,498] {taskinstance.py:1358} INFO - 
--------------------------------------------------------------------------------
[2023-04-22 09:37:38,512] {taskinstance.py:1377} INFO - Executing <Task(PythonOperator): clean_market_data> on 2023-04-22 09:36:20.516292+00:00
[2023-04-22 09:37:38,516] {standard_task_runner.py:52} INFO - Started process 1036 to run task
[2023-04-22 09:37:38,520] {standard_task_runner.py:79} INFO - Running: ['***', 'tasks', 'run', 'market_data_alphavantage_dag', 'clean_market_data', 'manual__2023-04-22T09:36:20.516292+00:00', '--job-id', '38', '--raw', '--subdir', 'DAGS_FOLDER/third.py', '--cfg-path', '/tmp/tmpdk8zr7kd', '--error-file', '/tmp/tmp3xtphhob']
[2023-04-22 09:37:38,521] {standard_task_runner.py:80} INFO - Job 38: Subtask clean_market_data
[2023-04-22 09:37:38,567] {task_command.py:369} INFO - Running <TaskInstance: market_data_alphavantage_dag.clean_market_data manual__2023-04-22T09:36:20.516292+00:00 [running]> on host 877f888c9ae3
[2023-04-22 09:37:38,634] {taskinstance.py:1571} INFO - Exporting the following env vars:
AIRFLOW_CTX_DAG_OWNER=***
AIRFLOW_CTX_DAG_ID=market_data_alphavantage_dag
AIRFLOW_CTX_TASK_ID=clean_market_data
AIRFLOW_CTX_EXECUTION_DATE=2023-04-22T09:36:20.516292+00:00
AIRFLOW_CTX_TRY_NUMBER=1
AIRFLOW_CTX_DAG_RUN_ID=manual__2023-04-22T09:36:20.516292+00:00
[2023-04-22 09:37:38,644] {taskinstance.py:1889} ERROR - Task failed with exception
Traceback (most recent call last):
  File "/home/airflow/.local/lib/python3.7/site-packages/airflow/operators/python.py", line 171, in execute
    return_value = self.execute_callable()
  File "/home/airflow/.local/lib/python3.7/site-packages/airflow/operators/python.py", line 189, in execute_callable
    return self.python_callable(*self.op_args, **self.op_kwargs)
  File "/opt/airflow/dags/third.py", line 43, in clean_market_data
    file=open(read_path+latest_file)
FileNotFoundError: [Errno 2] No such file or directory: '/opt/airflow/data/DATA_CENTER/DATA_LAKEstock_market_raw_data_I_1682156256.3001113'
[2023-04-22 09:37:38,654] {taskinstance.py:1400} INFO - Marking task as UP_FOR_RETRY. dag_id=market_data_alphavantage_dag, task_id=clean_market_data, execution_date=20230422T093620, start_date=20230422T093738, end_date=20230422T093738
[2023-04-22 09:37:38,665] {standard_task_runner.py:97} ERROR - Failed to execute job 38 for task clean_market_data ([Errno 2] No such file or directory: '/opt/airflow/data/DATA_CENTER/DATA_LAKEstock_market_raw_data_I_1682156256.3001113'; 1036)
[2023-04-22 09:37:38,692] {local_task_job.py:156} INFO - Task exited with return code 1
[2023-04-22 09:37:38,723] {local_task_job.py:273} INFO - 0 downstream tasks scheduled from follow-on schedule check
